scripts/randomizedTests/1-19.in
#basic-partial-exec
40
0-39 o
0 B 1 AAPL 2705 30
13 B 53 AAPL 2705 30
7 S 32 MSFT 2705 15
30 S 122 AAPL 2705 15
34 B 139 MSFT 2705 30
28 S 116 MSFT 2705 15
3 B 13 AAPL 2705 30
29 B 117 AAPL 2705 30
18 S 76 MSFT 2705 15
35 B 143 MSFT 2705 30
36 S 146 AAPL 2705 15
27 S 110 AAPL 2705 15
0 S 4 MSFT 2705 15
19 S 80 MSFT 2705 15
22 B 89 AAPL 2705 30
17 B 69 AAPL 2705 30
2 S 10 AAPL 2705 15
11 B 45 AAPL 2705 30
25 S 104 MSFT 2705 15
18 B 75 MSFT 2705 30
32 S 132 MSFT 2705 15
38 S 154 AAPL 2705 15
12 B 49 AAPL 2705 30
22 B 91 MSFT 2705 30
17 S 70 AAPL 2705 15
24 S 98 AAPL 2705 15
34 S 138 AAPL 2705 15
9 B 39 MSFT 2705 30
26 B 107 MSFT 2705 30
4 S 20 MSFT 2705 15
5 B 21 AAPL 2705 30
36 S 148 MSFT 2705 15
2 B 11 MSFT 2705 30
1 B 7 MSFT 2705 30
14 S 58 AAPL 2705 15
8 B 33 AAPL 2705 30
2 B 9 AAPL 2705 30
6 B 25 AAPL 2705 30
14 B 59 MSFT 2705 30
6 B 27 MSFT 2705 30
36 B 147 MSFT 2705 30
1 B 5 AAPL 2705 30
10 S 44 MSFT 2705 15
3 B 15 MSFT 2705 30
23 B 95 MSFT 2705 30
9 B 37 AAPL 2705 30
33 S 136 MSFT 2705 15
16 B 65 AAPL 2705 30
13 B 55 MSFT 2705 30
24 B 99 MSFT 2705 30
29 S 120 MSFT 2705 15
7 B 29 AAPL 2705 30
12 S 50 AAPL 2705 15
12 B 51 MSFT 2705 30
28 B 113 AAPL 2705 30
21 B 85 AAPL 2705 30
16 B 67 MSFT 2705 30
10 B 43 MSFT 2705 30
16 S 68 MSFT 2705 15
3 S 16 MSFT 2705 15
5 S 22 AAPL 2705 15
32 B 129 AAPL 2705 30
30 B 121 AAPL 2705 30
1 S 8 MSFT 2705 15
20 S 84 MSFT 2705 15
4 S 18 AAPL 2705 15
5 S 24 MSFT 2705 15
9 S 38 AAPL 2705 15
31 S 126 AAPL 2705 15
35 S 142 AAPL 2705 15
14 S 60 MSFT 2705 15
33 B 133 AAPL 2705 30
25 B 101 AAPL 2705 30
25 B 103 MSFT 2705 30
26 B 105 AAPL 2705 30
38 B 155 MSFT 2705 30
31 B 125 AAPL 2705 30
39 S 158 AAPL 2705 15
27 S 112 MSFT 2705 15
4 B 19 MSFT 2705 30
13 S 56 MSFT 2705 15
24 B 97 AAPL 2705 30
15 B 63 MSFT 2705 30
25 S 102 AAPL 2705 15
26 S 106 AAPL 2705 15
23 B 93 AAPL 2705 30
19 B 79 MSFT 2705 30
21 B 87 MSFT 2705 30
15 S 64 MSFT 2705 15
32 S 130 AAPL 2705 15
5 B 23 MSFT 2705 30
32 B 131 MSFT 2705 30
4 B 17 AAPL 2705 30
16 S 66 AAPL 2705 15
20 B 81 AAPL 2705 30
37 S 152 MSFT 2705 15
38 B 153 AAPL 2705 30
20 S 82 AAPL 2705 15
31 S 128 MSFT 2705 15
19 B 77 AAPL 2705 30
28 S 114 AAPL 2705 15
27 B 109 AAPL 2705 30
23 S 96 MSFT 2705 15
31 B 127 MSFT 2705 30
8 B 35 MSFT 2705 30
34 B 137 AAPL 2705 30
27 B 111 MSFT 2705 30
7 S 30 AAPL 2705 15
11 S 48 MSFT 2705 15
39 B 157 AAPL 2705 30
14 B 57 AAPL 2705 30
21 S 86 AAPL 2705 15
10 S 42 AAPL 2705 15
28 B 115 MSFT 2705 30
38 S 156 MSFT 2705 15
39 S 160 MSFT 2705 15
2 S 12 MSFT 2705 15
6 S 26 AAPL 2705 15
35 B 141 AAPL 2705 30
20 B 83 MSFT 2705 30
0 B 3 MSFT 2705 30
11 B 47 MSFT 2705 30
19 S 78 AAPL 2705 15
29 S 118 AAPL 2705 15
29 B 119 MSFT 2705 30
1 S 6 AAPL 2705 15
24 S 100 MSFT 2705 15
23 S 94 AAPL 2705 15
10 B 41 AAPL 2705 30
9 S 40 MSFT 2705 15
6 S 28 MSFT 2705 15
30 S 124 MSFT 2705 15
21 S 88 MSFT 2705 15
8 S 34 AAPL 2705 15
15 S 62 AAPL 2705 15
15 B 61 AAPL 2705 30
37 S 150 AAPL 2705 15
26 S 108 MSFT 2705 15
17 B 71 MSFT 2705 30
3 S 14 AAPL 2705 15
18 S 74 AAPL 2705 15
35 S 144 MSFT 2705 15
0 S 2 AAPL 2705 15
8 S 36 MSFT 2705 15
33 S 134 AAPL 2705 15
7 B 31 MSFT 2705 30
36 B 145 AAPL 2705 30
22 S 90 AAPL 2705 15
12 S 52 MSFT 2705 15
18 B 73 AAPL 2705 30
22 S 92 MSFT 2705 15
39 B 159 MSFT 2705 30
37 B 151 MSFT 2705 30
33 B 135 MSFT 2705 30
37 B 149 AAPL 2705 30
34 S 140 MSFT 2705 15
11 S 46 AAPL 2705 15
17 S 72 MSFT 2705 15
30 B 123 MSFT 2705 30
13 S 54 AAPL 2705 15
.
0-39 x
