scripts/randomizedTests/1-20.in
#basic-pricetime-vs-time
40
0-39 o
38 S 611 AAPL 1000 1
11 S 177 AAPL 2000 1
7 B 125 MSFT 5000 1
30 B 495 MSFT 5000 1
14 B 237 MSFT 5000 1
7 S 121 MSFT 2000 1
15 B 246 AAPL 5000 1
32 S 516 AAPL 1000 1
9 S 154 MSFT 2000 1
28 B 462 MSFT 5000 1
9 S 145 AAPL 2000 1
29 B 472 AAPL 5000 1
36 B 591 MSFT 5000 1
6 B 101 AAPL 5000 1
38 S 619 MSFT 1000 1
34 S 554 MSFT 2000 1
39 S 635 MSFT 1000 1
16 B 270 MSFT 5000 1
2 S 43 MSFT 1000 1
27 S 435 AAPL 1000 1
7 S 123 MSFT 1000 1
38 B 614 AAPL 5000 1
39 B 639 MSFT 5000 1
24 B 389 AAPL 5000 1
21 S 345 MSFT 2000 1
26 S 426 MSFT 2000 1
13 S 211 AAPL 1000 1
5 B 88 AAPL 5000 1
14 B 232 AAPL 5000 1
15 S 251 MSFT 1000 1
10 S 172 MSFT 1000 1
10 S 170 MSFT 2000 1
13 S 212 AAPL 1000 1
9 B 160 MSFT 5000 1
5 S 90 MSFT 2000 1
7 S 124 MSFT 1000 1
9 B 151 AAPL 5000 1
3 B 61 MSFT 5000 1
36 B 584 AAPL 5000 1
30 S 492 MSFT 1000 1
9 S 156 MSFT 1000 1
3 S 52 AAPL 1000 1
16 S 257 AAPL 2000 1
0 S 12 MSFT 1000 1
15 B 253 MSFT 5000 1
31 S 505 MSFT 2000 1
27 S 433 AAPL 2000 1
15 B 248 AAPL 5000 1
9 B 159 MSFT 5000 1
37 S 602 MSFT 2000 1
28 B 455 AAPL 5000 1
32 B 520 AAPL 5000 1
7 B 117 AAPL 5000 1
33 B 543 MSFT 5000 1
24 S 396 MSFT 1000 1
11 B 190 MSFT 5000 1
39 B 637 MSFT 5000 1
23 S 379 MSFT 1000 1
37 B 605 MSFT 5000 1
30 B 494 MSFT 5000 1
6 B 103 AAPL 5000 1
31 B 502 AAPL 5000 1
7 B 126 MSFT 5000 1
25 B 414 MSFT 5000 1
36 S 586 MSFT 2000 1
31 S 500 AAPL 1000 1
34 S 555 MSFT 1000 1
2 S 44 MSFT 1000 1
29 B 469 AAPL 5000 1
17 B 280 AAPL 5000 1
4 S 76 MSFT 1000 1
30 S 489 MSFT 2000 1
17 S 274 AAPL 2000 1
8 S 138 MSFT 2000 1
38 B 623 MSFT 5000 1
13 B 221 MSFT 5000 1
24 S 387 AAPL 1000 1
28 S 449 AAPL 2000 1
34 B 551 AAPL 5000 1
33 B 536 AAPL 5000 1
25 B 416 MSFT 5000 1
6 B 110 MSFT 5000 1
11 S 180 AAPL 1000 1
10 B 173 MSFT 5000 1
5 S 81 AAPL 2000 1
3 B 63 MSFT 5000 1
32 B 518 AAPL 5000 1
6 S 106 MSFT 2000 1
37 S 603 MSFT 1000 1
1 B 23 AAPL 5000 1
34 B 549 AAPL 5000 1
31 S 506 MSFT 2000 1
39 B 629 AAPL 5000 1
4 B 79 MSFT 5000 1
22 S 354 AAPL 2000 1
26 B 423 AAPL 5000 1
9 S 148 AAPL 1000 1
28 B 463 MSFT 5000 1
7 B 127 MSFT 5000 1
5 S 92 MSFT 1000 1
30 B 488 AAPL 5000 1
23 S 377 MSFT 2000 1
37 B 599 AAPL 5000 1
2 S 41 MSFT 2000 1
28 B 453 AAPL 5000 1
18 S 300 MSFT 1000 1
5 S 82 AAPL 2000 1
22 B 357 AAPL 5000 1
32 S 521 MSFT 2000 1
15 B 247 AAPL 5000 1
27 S 441 MSFT 2000 1
32 S 523 MSFT 1000 1
28 S 457 MSFT 2000 1
25 B 405 AAPL 5000 1
27 B 437 AAPL 5000 1
3 S 57 MSFT 2000 1
20 S 323 AAPL 1000 1
7 S 113 AAPL 2000 1
26 B 432 MSFT 5000 1
29 B 470 AAPL 5000 1
34 B 552 AAPL 5000 1
25 B 413 MSFT 5000 1
11 B 181 AAPL 5000 1
8 B 135 AAPL 5000 1
37 B 598 AAPL 5000 1
21 B 351 MSFT 5000 1
12 S 195 AAPL 1000 1
10 S 161 AAPL 2000 1
34 S 547 AAPL 1000 1
13 B 214 AAPL 5000 1
19 S 313 MSFT 2000 1
23 B 376 AAPL 5000 1
4 S 65 AAPL 2000 1
39 S 633 MSFT 2000 1
12 B 199 AAPL 5000 1
36 B 589 MSFT 5000 1
37 S 593 AAPL 2000 1
36 S 578 AAPL 2000 1
24 B 400 MSFT 5000 1
15 S 249 MSFT 2000 1
22 S 353 AAPL 2000 1
1 S 25 MSFT 2000 1
33 B 541 MSFT 5000 1
33 S 532 AAPL 1000 1
31 B 510 MSFT 5000 1
26 S 427 MSFT 1000 1
28 S 451 AAPL 1000 1
24 S 386 AAPL 2000 1
14 S 236 MSFT 1000 1
4 S 74 MSFT 2000 1
11 B 189 MSFT 5000 1
16 S 266 MSFT 2000 1
6 B 109 MSFT 5000 1
27 B 447 MSFT 5000 1
9 S 146 AAPL 2000 1
0 B 6 AAPL 5000 1
24 B 398 MSFT 5000 1
29 S 473 MSFT 2000 1
10 S 171 MSFT 1000 1
31 S 508 MSFT 1000 1
35 S 570 MSFT 2000 1
17 S 273 AAPL 2000 1
25 B 406 AAPL 5000 1
36 S 588 MSFT 1000 1
23 S 369 AAPL 2000 1
36 B 592 MSFT 5000 1
15 B 256 MSFT 5000 1
24 S 395 MSFT 1000 1
20 S 330 MSFT 2000 1
15 S 244 AAPL 1000 1
15 S 243 AAPL 1000 1
37 S 594 AAPL 2000 1
13 S 218 MSFT 2000 1
17 B 285 MSFT 5000 1
30 S 490 MSFT 2000 1
21 B 343 AAPL 5000 1
24 B 399 MSFT 5000 1
12 B 198 AAPL 5000 1
14 S 233 MSFT 2000 1
3 B 64 MSFT 5000 1
39 S 634 MSFT 2000 1
16 B 269 MSFT 5000 1
5 B 93 MSFT 5000 1
31 B 504 AAPL 5000 1
35 B 565 AAPL 5000 1
24 S 388 AAPL 1000 1
23 S 380 MSFT 1000 1
0 B 14 MSFT 5000 1
26 S 417 AAPL 2000 1
6 S 108 MSFT 1000 1
8 B 141 MSFT 5000 1
34 S 545 AAPL 2000 1
37 S 595 AAPL 1000 1
15 S 242 AAPL 2000 1
35 B 568 AAPL 5000 1
22 B 366 MSFT 5000 1
23 S 371 AAPL 1000 1
18 S 297 MSFT 2000 1
37 B 597 AAPL 5000 1
25 S 402 AAPL 2000 1
16 S 259 AAPL 1000 1
39 S 628 AAPL 1000 1
38 S 610 AAPL 2000 1
5 S 89 MSFT 2000 1
38 B 622 MSFT 5000 1
26 S 418 AAPL 2000 1
29 S 475 MSFT 1000 1
21 S 338 AAPL 2000 1
27 S 443 MSFT 1000 1
25 S 412 MSFT 1000 1
13 S 220 MSFT 1000 1
33 B 533 AAPL 5000 1
10 S 163 AAPL 1000 1
29 S 476 MSFT 1000 1
7 S 122 MSFT 2000 1
9 S 153 MSFT 2000 1
21 S 347 MSFT 1000 1
4 S 66 AAPL 2000 1
32 B 526 MSFT 5000 1
26 S 425 MSFT 2000 1
31 S 507 MSFT 1000 1
22 S 355 AAPL 1000 1
28 S 458 MSFT 2000 1
27 B 440 AAPL 5000 1
6 S 99 AAPL 1000 1
2 B 39 AAPL 5000 1
21 B 341 AAPL 5000 1
4 B 70 AAPL 5000 1
15 S 241 AAPL 2000 1
12 B 200 AAPL 5000 1
5 B 96 MSFT 5000 1
30 B 496 MSFT 5000 1
11 S 178 AAPL 2000 1
17 B 279 AAPL 5000 1
0 S 11 MSFT 1000 1
2 B 40 AAPL 5000 1
16 S 260 AAPL 1000 1
5 S 91 MSFT 1000 1
25 S 411 MSFT 1000 1
17 S 281 MSFT 2000 1
12 S 203 MSFT 1000 1
36 B 581 AAPL 5000 1
1 S 18 AAPL 2000 1
1 S 17 AAPL 2000 1
18 B 302 MSFT 5000 1
10 B 175 MSFT 5000 1
21 S 348 MSFT 1000 1
3 B 62 MSFT 5000 1
19 B 312 AAPL 5000 1
11 B 183 AAPL 5000 1
27 B 445 MSFT 5000 1
34 B 557 MSFT 5000 1
30 B 493 MSFT 5000 1
29 S 474 MSFT 2000 1
20 B 327 AAPL 5000 1
2 B 47 MSFT 5000 1
9 B 157 MSFT 5000 1
0 S 3 AAPL 1000 1
19 B 319 MSFT 5000 1
2 S 35 AAPL 1000 1
10 S 162 AAPL 2000 1
8 S 140 MSFT 1000 1
31 B 501 AAPL 5000 1
32 S 522 MSFT 2000 1
0 B 8 AAPL 5000 1
23 B 382 MSFT 5000 1
39 B 640 MSFT 5000 1
38 B 624 MSFT 5000 1
23 B 374 AAPL 5000 1
13 S 217 MSFT 2000 1
18 B 301 MSFT 5000 1
3 B 56 AAPL 5000 1
33 S 531 AAPL 1000 1
36 S 587 MSFT 1000 1
35 S 571 MSFT 1000 1
26 B 430 MSFT 5000 1
28 S 460 MSFT 1000 1
17 B 287 MSFT 5000 1
33 B 534 AAPL 5000 1
7 S 114 AAPL 2000 1
7 B 118 AAPL 5000 1
37 S 596 AAPL 1000 1
4 B 69 AAPL 5000 1
12 S 201 MSFT 2000 1
10 B 166 AAPL 5000 1
12 S 204 MSFT 1000 1
1 B 24 AAPL 5000 1
13 B 216 AAPL 5000 1
34 S 546 AAPL 2000 1
37 B 606 MSFT 5000 1
18 B 303 MSFT 5000 1
23 B 375 AAPL 5000 1
21 B 352 MSFT 5000 1
38 S 612 AAPL 1000 1
3 B 54 AAPL 5000 1
20 S 329 MSFT 2000 1
36 S 577 AAPL 2000 1
3 B 53 AAPL 5000 1
31 B 511 MSFT 5000 1
14 S 227 AAPL 1000 1
20 S 321 AAPL 2000 1
35 S 562 AAPL 2000 1
22 B 367 MSFT 5000 1
25 B 408 AAPL 5000 1
4 B 71 AAPL 5000 1
38 S 620 MSFT 1000 1
10 S 164 AAPL 1000 1
13 B 222 MSFT 5000 1
8 B 134 AAPL 5000 1
34 S 548 AAPL 1000 1
16 S 267 MSFT 1000 1
18 S 298 MSFT 2000 1
23 B 383 MSFT 5000 1
25 B 407 AAPL 5000 1
20 B 328 AAPL 5000 1
28 S 459 MSFT 1000 1
4 S 73 MSFT 2000 1
31 S 497 AAPL 2000 1
20 S 324 AAPL 1000 1
32 S 524 MSFT 1000 1
19 S 314 MSFT 2000 1
14 B 231 AAPL 5000 1
17 S 275 AAPL 1000 1
27 B 439 AAPL 5000 1
6 B 102 AAPL 5000 1
3 S 59 MSFT 1000 1
13 B 223 MSFT 5000 1
18 B 293 AAPL 5000 1
19 B 320 MSFT 5000 1
34 B 558 MSFT 5000 1
16 B 261 AAPL 5000 1
10 B 165 AAPL 5000 1
3 S 50 AAPL 2000 1
1 S 19 AAPL 1000 1
8 B 142 MSFT 5000 1
8 B 133 AAPL 5000 1
18 B 295 AAPL 5000 1
16 S 258 AAPL 2000 1
18 S 292 AAPL 1000 1
32 S 514 AAPL 2000 1
20 S 332 MSFT 1000 1
0 S 2 AAPL 2000 1
14 S 225 AAPL 2000 1
17 S 276 AAPL 1000 1
2 B 38 AAPL 5000 1
0 S 10 MSFT 2000 1
5 B 85 AAPL 5000 1
9 B 149 AAPL 5000 1
37 S 604 MSFT 1000 1
10 B 176 MSFT 5000 1
1 B 32 MSFT 5000 1
12 B 206 MSFT 5000 1
25 B 415 MSFT 5000 1
27 S 436 AAPL 1000 1
36 B 583 AAPL 5000 1
38 S 618 MSFT 2000 1
1 B 21 AAPL 5000 1
35 B 567 AAPL 5000 1
33 S 540 MSFT 1000 1
4 B 72 AAPL 5000 1
17 B 288 MSFT 5000 1
5 S 84 AAPL 1000 1
28 S 450 AAPL 2000 1
1 B 30 MSFT 5000 1
31 B 509 MSFT 5000 1
6 B 111 MSFT 5000 1
17 B 286 MSFT 5000 1
13 B 213 AAPL 5000 1
14 S 226 AAPL 2000 1
21 B 349 MSFT 5000 1
24 S 393 MSFT 2000 1
33 B 542 MSFT 5000 1
30 S 481 AAPL 2000 1
38 B 616 AAPL 5000 1
19 B 309 AAPL 5000 1
8 S 137 MSFT 2000 1
1 B 29 MSFT 5000 1
17 S 282 MSFT 2000 1
19 S 308 AAPL 1000 1
25 S 409 MSFT 2000 1
8 B 143 MSFT 5000 1
10 B 167 AAPL 5000 1
27 B 448 MSFT 5000 1
5 B 94 MSFT 5000 1
14 B 229 AAPL 5000 1
28 S 452 AAPL 1000 1
4 S 75 MSFT 1000 1
37 B 607 MSFT 5000 1
