scripts/randomizedTests/1-basic-example2-3threads.in
3
o
1 B 12 MSFT 3290 29
0 B 3 AAPL 3290 29
0 S 4 MSFT 3250 4
2 S 13 AAPL 3250 4
1 S 10 MSFT 3250 4
0 S 1 AAPL 3250 4
2 B 18 MSFT 3290 29
1 B 9 AAPL 3290 29
2 B 15 AAPL 3290 29
1 S 11 MSFT 3260 25
2 S 16 MSFT 3250 4
2 S 17 MSFT 3260 25
1 S 8 AAPL 3260 25
0 B 6 MSFT 3290 29
0 S 5 MSFT 3260 25
2 S 14 AAPL 3260 25
0 S 2 AAPL 3260 25
1 S 7 AAPL 3250 4
.
x
